Workbook
Name SegmentaçãoDeDados_Aplicativo: #N/A
Name SegmentaçãoDeDados_Aplicativo1: #N/A
Name SegmentaçãoDeDados_Data: #N/A
Name SegmentaçãoDeDados_Data1: #N/A
Name SegmentaçãoDeDados_Mês: #N/A
Name SegmentaçãoDeDados_Mês1: #N/A

Sheet Dashbord
D10: Receita Total | I10: Lucro Líquido | N10: Ganho por Hora | T10: Lucro por KM | Y10: KM Rodados | AE10: Total de Corridas
D12: =GETPIVOTDATA("Soma de Valor",'Tabela Dinamica'!$A$3) -> 11430.83 | I12: =GETPIVOTDATA("Soma de Lucro Líquido ",'Tabela Dinamica'!$A$3) -> 5541.16 | N12: ='Tabela Dinamica'!A2 -> 20.004188 | T12: ='Tabela Dinamica'!B2 -> 0.62485524 | Y12: =GETPIVOTDATA("Soma de Km",'Tabela Dinamica'!$A$3) -> 8867.91 | AE12: =GETPIVOTDATA("Soma de Corrida",'Tabela Dinamica'!$A$3) -> 422
T29: 0
T39: Receita por Corrida | Z39: Custo por KM
T41: ='Tabela Dinamica'!C2 -> 27.087275 | Z41: ='Tabela Dinamica'!G2 -> 0.66415536
C45: Dias Trabalhados
T46: Corrida por Hora | Z46: KM por Corrida
C47: =GETPIVOTDATA("[Measures].[Contagem Distinta de Data]",'Tabela Dinamica'!$E$19) -> 35
T48: ='Tabela Dinamica'!H2 -> 1.5234657 | Z48: ='Tabela Dinamica'!F2 -> 21.014005
C51: Horas Trabalhadas
C53: =GETPIVOTDATA("Soma de Horas",'Tabela Dinamica'!$A$3) -> 277 | T53: Consumo Médio por KM/L | Z53: Lucro Médio por Dia
T55: ='Tabela Dinamica'!D2 -> 8.0463751 | Z55: ='Tabela Dinamica'!E2 -> 158.31886
C57: Total de Corridas
C59: =GETPIVOTDATA("Soma de Corrida",'Tabela Dinamica'!$A$3) -> 422
C63: KM Rodados
C65: =GETPIVOTDATA("Soma de Km",'Tabela Dinamica'!$A$3) -> 8867.91

Sheet Tabela Dinamica
A1: Ganho por Hora | B1: Lucro por KM | C1: Receita por Corrida | D1: Consumo Médio (KM/L) | E1: Lucro Médio por Dia | F1: KM por Corrida | G1: Custo por KM | H1: Corrida por Hora
A2: =GETPIVOTDATA("Soma de Lucro Líquido ",$A$3)/GETPIVOTDATA("Soma de Horas",$A$3) -> 20.004188 | B2: =GETPIVOTDATA("Soma de Lucro Líquido ",$A$3)/GETPIVOTDATA("Soma de Km",$A$3) -> 0.62485524 | C2: =GETPIVOTDATA("Soma de Valor",$A$3)/GETPIVOTDATA("Soma de Corrida",$A$3) -> 27.087275 | D2: =GETPIVOTDATA("Soma de Km",$A$3)/GETPIVOTDATA("Soma de Litros",$A$3) -> 8.0463751 | E2: =GETPIVOTDATA("Soma de Lucro Líquido ",$A$3)/GETPIVOTDATA("[Measures].[Contagem Distinta de Data]",$E$19) -> 158.31886 | F2: =GETPIVOTDATA("Soma de Km",$A$3)/GETPIVOTDATA("Soma de Corrida",$A$3) -> 21.014005 | G2: =K4/GETPIVOTDATA("Soma de Km",$A$3) -> 0.66415536 | H2: =GETPIVOTDATA("Soma de Corrida",$A$3)/GETPIVOTDATA("Soma de Horas",$A$3) -> 1.5234657
A3: Soma de Valor | B3: Soma de Lucro Líquido | C3: Soma de Horas | D3: Soma de Km | E3: Soma de Corrida | F3: Soma de Receita | G3: Soma de Litros | H3: Soma de Combustível | I3: Soma de Alimentação | J3: Soma de Manutenção | K3: Total
A4: 11430.83 | B4: 5541.16 | C4: 277 | D4: 8867.91 | E4: 422 | F4: 6745.49 | G4: 1102.1 | H4: 4685.34 | I4: 299.99 | J4: 904.34 | K4: =GETPIVOTDATA("Soma de Combustível",$H$3)+GETPIVOTDATA("Soma de Alimentação",$H$3)+GETPIVOTDATA("Soma de Manutenção",$H$3) -> 5889.67
A7: Rótulos de Linha | B7: Soma de Receita | C7: Soma de Valor | E7: Rótulos de Linha | F7: Soma de Valor
A8: dom | B8: 1741.48 | C8: 2730.93 | E8: dom | F8: 2730.93
A9: qui | B9: 606.42 | C9: 1791.38 | E9: qui | F9: 1791.38
A10: sex | B10: 2032.69 | C10: 3243.77 | E10: sex | F10: 3243.77
A11: sáb | B11: 2364.9 | C11: 3664.75 | E11: sáb | F11: 3664.75
A12: Total Geral | B12: 6745.49 | C12: 11430.83 | E12: Total Geral | F12: 11430.83
A14: Rótulos de Linha | B14: Soma de Receita | C14: Soma de Valor | E14: Rótulos de Linha | F14: Soma de Corrida
A15: março | B15: 1830.02 | C15: 3370.82 | E15: 99 | F15: 198
A16: abril | B16: 542.3 | C16: 975.85 | E16: Uber | F16: 224
A17: maio | B17: 1731.92 | C17: 2993.89 | E17: Total Geral | F17: 422
A18: junho | B18: 975.35 | C18: 1581.96
A19: julho | B19: 1665.9 | C19: 2508.31 | E19: Contagem Distinta de Data
A20: Total Geral | B20: 6745.49 | C20: 11430.83 | E20: 35

Sheet Registro
A1: Data | B1: Dia | C1: Mês | D1: ANO | E1: Semana | F1: Semana ano | G1: Tipo dia | H1: Aplicativo | I1: Corrida | J1: Km | K1: Horas | L1: Valor | M1: Receita | N1: Combustível | O1: Litros | P1: Tipo Combustivel | Q1: Alimentação | R1: Manutenção | S1: Lucro Líquido | T1: Km/L | U1: Ganho por horas | V1: Ganho por km | W1: Valor Medio Corrida | X1: Media KM Corrida
A2: 46088 | B2: =IF(A2="","",TEXT(A2,"d")) -> 7 | C2: =IF(A2="","",TEXT(A2,"mmmm")) -> março | D2: =IF(A2="","",YEAR(A2)) -> 2026 | E2: =IF(A2="","",TEXT(A2,"ddd")) -> sáb | F2: =IF(A2="","",WEEKNUM(A2)) -> 10 | G2: =IF(A2="","",IF(WEEKDAY(A2,2)>5,"Final de semana","Semana")) -> Final de semana | H2: Uber | I2: 9 | J2: 200 | K2: 7 | L2: 233.52 | M2: =SUM(Tabela1[[#This Row],[Valor]]-Tabela1[[#This Row],[Combustível]]) -> 98.82 | N2: 134.7 | O2: 15 | P2: Etanol | Q2: 0 | R2: 0 | S2: =SUM(Tabela1[[#This Row],[Valor]]-Tabela1[[#This Row],[Alimentação]]-Tabela1[[#This Row],[Manutenção]]-Tabela1[[#This Row],[Combustível]]) -> 98.82 | T2: 9.6 | U2: =IFERROR(Tabela1[[#This Row],[Km]]/Tabela1[[#This Row],[Horas]],"") -> 28.571429 | V2: =IFERROR(Tabela1[[#This Row],[Valor]]/Tabela1[[#This Row],[Km]],"") -> 1.1676 | W2: =IFERROR(Tabela1[[#This Row],[Valor]]/Tabela1[[#This Row],[Corrida]],"") -> 25.946667 | X2: =IFERROR(Tabela1[[#This Row],[Km]]/Tabela1[[#This Row],[Corrida]],"") -> 22.222222
A3: 46088 | B3: =IF(A3="","",TEXT(A3,"d")) -> 7 | C3: =IF(A3="","",TEXT(A3,"mmmm")) -> março | D3: =IF(A3="","",YEAR(A3)) -> 2026 | E3: =IF(A3="","",TEXT(A3,"ddd")) -> sáb | F3: =IF(A3="","",WEEKNUM(A3)) -> 10 | G3: =IF(A3="","",IF(WEEKDAY(A3,2)>5,"Final de semana","Semana")) -> Final de semana | H3: 99 | I3: 3 | J3: 81.6 | K3: 1 | L3: 106.93 | M3: =SUM(Tabela1[[#This Row],[Valor]]-Tabela1[[#This Row],[Combustível]]) -> 106.93 | N3: 0 | O3: 0 | P3: Etanol | Q3: 0 | R3: 0 | S3: =SUM(Tabela1[[#This Row],[Valor]]-Tabela1[[#This Row],[Alimentação]]-Tabela1[[#This Row],[Manutenção]]-Tabela1[[#This Row],[Combustível]]) -> 106.93 | T3: 9.6 | U3: =IFERROR(Tabela1[[#This Row],[Km]]/Tabela1[[#This Row],[Horas]],"") -> 81.6 | V3: =IFERROR(Tabela1[[#This Row],[Valor]]/Tabela1[[#This Row],[Km]],"") -> 1.3104167 | W3: =IFERROR(Tabela1[[#This Row],[Valor]]/Tabela1[[#This Row],[Corrida]],"") -> 35.643333 | X3: =IFERROR(Tabela1[[#This Row],[Km]]/Tabela1[[#This Row],[Corrida]],"") -> 27.2
A4: 46093 | B4: =IF(A4="","",TEXT(A4,"d")) -> 12 | C4: =IF(A4="","",TEXT(A4,"mmmm")) -> março | D4: =IF(A4="","",YEAR(A4)) -> 2026 | E4: =IF(A4="","",TEXT(A4,"ddd")) -> qui | F4: =IF(A4="","",WEEKNUM(A4)) -> 11 | G4: =IF(A4="","",IF(WEEKDAY(A4,2)>5,"Final de semana","Semana")) -> Semana | H4: 99 | I4: 13 | J4: 110.4 | K4: 4 | L4: 192.08 | M4: =SUM(Tabela1[[#This Row],[Valor]]-Tabela1[[#This Row],[Combustível]]) -> 92.86 | N4: 99.22 | O4: 20 | P4: Etanol | Q4: 11.99 | R4: 0 | S4: =SUM(Tabela1[[#This Row],[Valor]]-Tabela1[[#This Row],[Alimentação]]-Tabela1[[#This Row],[Manutenção]]-Tabela1[[#This Row],[Combustível]]) -> 80.87 | T4: 9 | U4: =IFERROR(Tabela1[[#This Row],[Km]]/Tabela1[[#This Row],[Horas]],"") -> 27.6 | V4: =IFERROR(Tabela1[[#This Row],[Valor]]/Tabela1[[#This Row],[Km]],"") -> 1.7398551 | W4: =IFERROR(Tabela1[[#This Row],[Valor]]/Tabela1[[#This Row],[Corrida]],"") -> 14.775385 | X4: =IFERROR(Tabela1[[#This Row],[Km]]/Tabela1[[#This Row],[Corrida]],"") -> 8.4923077
A5: 46093 | B5: =IF(A5="","",TEXT(A5,"d")) -> 12 | C5: =IF(A5="","",TEXT(A5,"mmmm")) -> março | D5: =IF(A5="","",YEAR(A5)) -> 2026 | E5: =IF(A5="","",TEXT(A5,"ddd")) -> qui | F5: =IF(A5="","",WEEKNUM(A5)) -> 11 | G5: =IF(A5="","",IF(WEEKDAY(A5,2)>5,"Final de semana","Semana")) -> Semana | H5: Uber | I5: 9 | J5: 138 | K5: 5 | L5: 139.38 | M5: =SUM(Tabela1[[#This Row],[Valor]]-Tabela1[[#This Row],[Combustível]]) -> 39.58 | N5: 99.8 | O5: 20 | P5: Etanol | Q5: 0 | R5: 0 | S5: =SUM(Tabela1[[#This Row],[Valor]]-Tabela1[[#This Row],[Alimentação]]-Tabela1[[#This Row],[Manutenção]]-Tabela1[[#This Row],[Combustível]]) -> 39.58 | T5: 9 | U5: =IFERROR(Tabela1[[#This Row],[Km]]/Tabela1[[#This Row],[Horas]],"") -> 27.6 | V5: =IFERROR(Tabela1[[#This Row],[Valor]]/Tabela1[[#This Row],[Km]],"") -> 1.01 | W5: =IFERROR(Tabela1[[#This Row],[Valor]]/Tabela1[[#This Row],[Corrida]],"") -> 15.486667 | X5: =IFERROR(Tabela1[[#This Row],[Km]]/Tabela1[[#This Row],[Corrida]],"") -> 15.333333
A6: 46094 | B6: =IF(A6="","",TEXT(A6,"d")) -> 13 | C6: =IF(A6="","",TEXT(A6,"mmmm")) -> março | D6: =IF(A6="","",YEAR(A6)) -> 2026 | E6: =IF(A6="","",TEXT(A6,"ddd")) -> sex | F6: =IF(A6="","",WEEKNUM(A6)) -> 11 | G6: =IF(A6="","",IF(WEEKDAY(A6,2)>5,"Final de semana","Semana")) -> Semana | H6: 99 | I6: 12 | J6: 129.9 | K6: 3 | L6: 169.36 | M6: =SUM(Tabela1[[#This Row],[Valor]]-Tabela1[[#This Row],[Combustível]]) -> 120.46 | N6: 48.9 | O6: 10 | P6: Etanol | Q6: 20 | R6: 0 | S6: =SUM(Tabela1[[#This Row],[Valor]]-Tabela1[[#This Row],[Alimentação]]-Tabela1[[#This Row],[Manutenção]]-Tabela1[[#This Row],[Combustível]]) -> 100.46 | T6: 8.9 | U6: =IFERROR(Tabela1[[#This Row],[Km]]/Tabela1[[#This Row],[Horas]],"") -> 43.3 | V6: =IFERROR(Tabela1[[#This Row],[Valor]]/Tabela1[[#This Row],[Km]],"") -> 1.3037721 | W6: =IFERROR(Tabela1[[#This Row],[Valor]]/Tabela1[[#This Row],[Corrida]],"") -> 14.113333 | X6: =IFERROR(Tabela1[[#This Row],[Km]]/Tabela1[[#This Row],[Corrida]],"") -> 10.825
A7: 46094 | B7: =IF(A7="","",TEXT(A7,"d")) -> 13 | C7: =IF(A7="","",TEXT(A7,"mmmm")) -> março | D7: =IF(A7="","",YEAR(A7)) -> 2026 | E7: =IF(A7="","",TEXT(A7,"ddd")) -> sex | F7: =IF(A7="","",WEEKNUM(A7)) -> 11 | G7: =IF(A7="","",IF(WEEKDAY(A7,2)>5,"Final de semana","Semana")) -> Semana | H7: Uber | I7: 5 | J7: 54.2 | K7: 2 | L7: 130 | M7: =SUM(Tabela1[[#This Row],[Valor]]-Tabela1[[#This Row],[Combustível]]) -> 81.1 | N7: 48.9 | O7: 10 | P7: Etanol | Q7: 20 | R7: 0 | S7: =SUM(Tabela1[[#This Row],[Valor]]-Tabela1[[#This Row],[Alimentação]]-Tabela1[[#This Row],[Manutenção]]-Tabela1[[#This Row],[Combustível]]) -> 61.1 | T7: 8.9 | U7: =IFERROR(Tabela1[[#This Row],[Km]]/Tabela1[[#This Row],[Horas]],"") -> 27.1 | V7: =IFERROR(Tabela1[[#This Row],[Valor]]/Tabela1[[#This Row],[Km]],"") -> 2.398524 | W7: =IFERROR(Tabela1[[#This Row],[Valor]]/Tabela1[[#This Row],[Corrida]],"") -> 26 | X7: =IFERROR(Tabela1[[#This Row],[Km]]/Tabela1[[#This Row],[Corrida]],"") -> 10.84
A8: 46096 | B8: =IF(A8="","",TEXT(A8,"d")) -> 15 | C8: =IF(A8="","",TEXT(A8,"mmmm")) -> março | D8: =IF(A8="","",YEAR(A8)) -> 2026 | E8: =IF(A8="","",TEXT(A8,"ddd")) -> dom | F8: =IF(A8="","",WEEKNUM(A8)) -> 12 | G8: =IF(A8="","",IF(WEEKDAY(A8,2)>5,"Final de semana","Semana")) -> Final de semana | H8: Uber | I8: 5 | J8: 125 | K8: 4 | L8: 117.55 | M8: =SUM(Tabela1[[#This Row],[Valor]]-Tabela1[[#This Row],[Combustível]]) -> 55.67 | N8: 61.88 | O8: 10 | P8: Etanol | Q8: 15 | R8: 0 | S8: =SUM(Tabela1[[#This Row],[Valor]]-Tabela1[[#This Row],[Alimentação]]-Tabela1[[#This Row],[Manutenção]]-Tabela1[[#This Row],[Combustível]]) -> 40.67 | T8: 10 | U8: =IFERROR(Tabela1[[#This Row],[Km]]/Tabela1[[#This Row],[Horas]],"") -> 31.25 | V8: =IFERROR(Tabela1[[#This Row],[Valor]]/Tabela1[[#This Row],[Km]],"") -> 0.9404 | W8: =IFERROR(Tabela1[[#This Row],[Valor]]/Tabela1[[#This Row],[Corrida]],"") -> 23.51 | X8: =IFERROR(Tabela1[[#This Row],[Km]]/Tabela1[[#This Row],[Corrida]],"") -> 25
A9: 46096 | B9: =IF(A9="","",TEXT(A9,"d")) -> 15 | C9: =IF(A9="","",TEXT(A9,"mmmm")) -> março | D9: =IF(A9="","",YEAR(A9)) -> 2026 | E9: =IF(A9="","",TEXT(A9,"ddd")) -> dom | F9: =IF(A9="","",WEEKNUM(A9)) -> 12 | G9: =IF(A9="","",IF(WEEKDAY(A9,2)>5,"Final de semana","Semana")) -> Final de semana | H9: 99 | I9: 7 | J9: 176 | K9: 4 | L9: 279.2 | M9: =SUM(Tabela1[[#This Row],[Valor]]-Tabela1[[#This Row],[Combustível]]) -> 217.32 | N9: 61.88 | O9: 15 | P9: Etanol | Q9: 15 | R9: 0 | S9: =SUM(Tabela1[[#This Row],[Valor]]-Tabela1[[#This Row],[Alimentação]]-Tabela1[[#This Row],[Manutenção]]-Tabela1[[#This Row],[Combustível]]) -> 202.32 | T9: 10 | U9: =IFERROR(Tabela1[[#This Row],[Km]]/Tabela1[[#This Row],[Horas]],"") -> 44 | V9: =IFERROR(Tabela1[[#This Row],[Valor]]/Tabela1[[#This Row],[Km]],"") -> 1.5863636 | W9: =IFERROR(Tabela1[[#This Row],[Valor]]/Tabela1[[#This Row],[Corrida]],"") -> 39.885714 | X9: =IFERROR(Tabela1[[#This Row],[Km]]/Tabela1[[#This Row],[Corrida]],"") -> 25.142857
A10: 46100 | B10: =IF(A10="","",TEXT(A10,"d")) -> 19 | C10: =IF(A10="","",TEXT(A10,"mmmm")) -> março | D10: =IF(A10="","",YEAR(A10)) -> 2026 | E10: =IF(A10="","",TEXT(A10,"ddd")) -> qui | F10: =IF(A10="","",WEEKNUM(A10)) -> 12 | G10: =IF(A10="","",IF(WEEKDAY(A10,2)>5,"Final de semana","Semana")) -> Semana | H10: Uber | I10: 7 | J10: 133 | K10: 5 | L10: 220.25 | M10: =SUM(Tabela1[[#This Row],[Valor]]-Tabela1[[#This Row],[Combustível]]) -> 122.45 | N10: 97.8 | O10: 20 | P10: Etanol | Q10: 0 | R10: 0 | S10: =SUM(Tabela1[[#This Row],[Valor]]-Tabela1[[#This Row],[Alimentação]]-Tabela1[[#This Row],[Manutenção]]-Tabela1[[#This Row],[Combustível]]) -> 122.45 | T10: 9.3 | U10: =IFERROR(Tabela1[[#This Row],[Km]]/Tabela1[[#This Row],[Horas]],"") -> 26.6 | V10: =IFERROR(Tabela1[[#This Row],[Valor]]/Tabela1[[#This Row],[Km]],"") -> 1.656015 | W10: =IFERROR(Tabela1[[#This Row],[Valor]]/Tabela1[[#This Row],[Corrida]],"") -> 31.464286 | X10: =IFERROR(Tabela1[[#This Row],[Km]]/Tabela1[[#This Row],[Corrida]],"") -> 19
A11: 46100 | B11: =IF(A11="","",TEXT(A11,"d")) -> 19 | C11: =IF(A11="","",TEXT(A11,"mmmm")) -> março | D11: =IF(A11="","",YEAR(A11)) -> 2026 | E11: =IF(A11="","",TEXT(A11,"ddd")) -> qui | F11: =IF(A11="","",WEEKNUM(A11)) -> 12 | G11: =IF(A11="","",IF(WEEKDAY(A11,2)>5,"Final de semana","Semana")) -> Semana | H11: 99 | I11: 7 | J11: 133 | K11: 3 | L11: 121.75 | M11: =SUM(Tabela1[[#This Row],[Valor]]-Tabela1[[#This Row],[Combustível]]) -> -27.95 | N11: 149.7 | O11: 30 | P11: Etanol | Q11: 0 | R11: 0 | S11: =SUM(Tabela1[[#This Row],[Valor]]-Tabela1[[#This Row],[Alimentação]]-Tabela1[[#This Row],[Manutenção]]-Tabela1[[#This Row],[Combustível]]) -> -27.95 | T11: 9.3 | U11: =IFERROR(Tabela1[[#This Row],[Km]]/Tabela1[[#This Row],[Horas]],"") -> 44.333333 | V11: =IFERROR(Tabela1[[#This Row],[Valor]]/Tabela1[[#This Row],[Km]],"") -> 0.91541353 | W11: =IFERROR(Tabela1[[#This Row],[Valor]]/Tabela1[[#This Row],[Corrida]],"") -> 17.392857 | X11: =IFERROR(Tabela1[[#This Row],[Km]]/Tabela1[[#This Row],[Corrida]],"") -> 19
A12: 46101 | B12: =IF(A12="","",TEXT(A12,"d")) -> 20 | C12: =IF(A12="","",TEXT(A12,"mmmm")) -> março | D12: =IF(A12="","",YEAR(A12)) -> 2026 | E12: =IF(A12="","",TEXT(A12,"ddd")) -> sex | F12: =IF(A12="","",WEEKNUM(A12)) -> 12 | G12: =IF(A12="","",IF(WEEKDAY(A12,2)>5,"Final de semana","Semana")) -> Semana | H12: Uber | I12: 5 | J12: 129.8 | K12: 5 | L12: 143.63 | M12: =SUM(Tabela1[[#This Row],[Valor]]-Tabela1[[#This Row],[Combustível]]) -> 68.78 | N12: 74.85 | O12: 15 | P12: Etanol | Q12: 0 | R12: 0 | S12: =SUM(Tabela1[[#This Row],[Valor]]-Tabela1[[#This Row],[Alimentação]]-Tabela1[[#This Row],[Manutenção]]-Tabela1[[#This Row],[Combustível]]) -> 68.78 | T12: 9.4 | U12: =IFERROR(Tabela1[[#This Row],[Km]]/Tabela1[[#This Row],[Horas]],"") -> 25.96 | V12: =IFERROR(Tabela1[[#This Row],[Valor]]/Tabela1[[#This Row],[Km]],"") -> 1.1065485 | W12: =IFERROR(Tabela1[[#This Row],[Valor]]/Tabela1[[#This Row],[Corrida]],"") -> 28.726 | X12: =IFERROR(Tabela1[[#This Row],[Km]]/Tabela1[[#This Row],[Corrida]],"") -> 25.96
A13: 46101 | B13: =IF(A13="","",TEXT(A13,"d")) -> 20 | C13: =IF(A13="","",TEXT(A13,"mmmm")) -> março | D13: =IF(A13="","",YEAR(A13)) -> 2026 | E13: =IF(A13="","",TEXT(A13,"ddd")) -> sex | F13: =IF(A13="","",WEEKNUM(A13)) -> 12 | G13: =IF(A13="","",IF(WEEKDAY(A13,2)>5,"Final de semana","Semana")) -> Semana | H13: 99 | I13: 4 | J13: 102.8 | K13: 3 | L13: 114.3 | M13: =SUM(Tabela1[[#This Row],[Valor]]-Tabela1[[#This Row],[Combustível]]) -> 64.4 | N13: 49.9 | O13: 10 | P13: Etanol | Q13: 0 | R13: 0 | S13: =SUM(Tabela1[[#This Row],[Valor]]-Tabela1[[#This Row],[Alimentação]]-Tabela1[[#This Row],[Manutenção]]-Tabela1[[#This Row],[Combustível]]) -> 64.4 | T13: 9.4 | U13: =IFERROR(Tabela1[[#This Row],[Km]]/Tabela1[[#This Row],[Horas]],"") -> 34.266667 | V13: =IFERROR(Tabela1[[#This Row],[Valor]]/Tabela1[[#This Row],[Km]],"") -> 1.1118677 | W13: =IFERROR(Tabela1[[#This Row],[Valor]]/Tabela1[[#This Row],[Corrida]],"") -> 28.575 | X13: =IFERROR(Tabela1[[#This Row],[Km]]/Tabela1[[#This Row],[Corrida]],"") -> 25.7
A14: 46103 | B14: =IF(A14="","",TEXT(A14,"d")) -> 22 | C14: =IF(A14="","",TEXT(A14,"mmmm")) -> março | D14: =IF(A14="","",YEAR(A14)) -> 2026 | E14: =IF(A14="","",TEXT(A14,"ddd")) -> dom | F14: =IF(A14="","",WEEKNUM(A14)) -> 13 | G14: =IF(A14="","",IF(WEEKDAY(A14,2)>5,"Final de semana","Semana")) -> Final de semana | H14: Uber | I14: 10 | J14: 240.7 | K14: 6 | L14: 275.08 | M14: =SUM(Tabela1[[#This Row],[Valor]]-Tabela1[[#This Row],[Combustível]]) -> 150.33 | N14: 124.75 | O14: 25 | P14: Etanol | Q14: 0 | R14: 0 | S14: =SUM(Tabela1[[#This Row],[Valor]]-Tabela1[[#This Row],[Alimentação]]-Tabela1[[#This Row],[Manutenção]]-Tabela1[[#This Row],[Combustível]]) -> 150.33 | T14: 9.7 | U14: =IFERROR(Tabela1[[#This Row],[Km]]/Tabela1[[#This Row],[Horas]],"") -> 40.116667 | V14: =IFERROR(Tabela1[[#This Row],[Valor]]/Tabela1[[#This Row],[Km]],"") -> 1.1428334 | W14: =IFERROR(Tabela1[[#This Row],[Valor]]/Tabela1[[#This Row],[Corrida]],"") -> 27.508 | X14: =IFERROR(Tabela1[[#This Row],[Km]]/Tabela1[[#This Row],[Corrida]],"") -> 24.07
A15: 46103 | B15: =IF(A15="","",TEXT(A15,"d")) -> 22 | C15: =IF(A15="","",TEXT(A15,"mmmm")) -> março | D15: =IF(A15="","",YEAR(A15)) -> 2026 | E15: =IF(A15="","",TEXT(A15,"ddd")) -> dom | F15: =IF(A15="","",WEEKNUM(A15)) -> 13 | G15: =IF(A15="","",IF(WEEKDAY(A15,2)>5,"Final de semana","Semana")) -> Final de semana | H15: 99 | I15: 3 | J15: 72.2 | K15: 2 | L15: 109.83 | M15: =SUM(Tabela1[[#This Row],[Valor]]-Tabela1[[#This Row],[Combustível]]) -> 12.03 | N15: 97.8 | O15: 20 | P15: Etanol | Q15: 0 | R15: 0 | S15: =SUM(Tabela1[[#This Row],[Valor]]-Tabela1[[#This Row],[Alimentação]]-Tabela1[[#This Row],[Manutenção]]-Tabela1[[#This Row],[Combustível]]) -> 12.03 | T15: 9.7 | U15: =IFERROR(Tabela1[[#This Row],[Km]]/Tabela1[[#This Row],[Horas]],"") -> 36.1 | V15: =IFERROR(Tabela1[[#This Row],[Valor]]/Tabela1[[#This Row],[Km]],"") -> 1.5211911 | W15: =IFERROR(Tabela1[[#This Row],[Valor]]/Tabela1[[#This Row],[Corrida]],"") -> 36.61 | X15: =IFERROR(Tabela1[[#This Row],[Km]]/Tabela1[[#This Row],[Corrida]],"") -> 24.066667
A16: 46107 | B16: =IF(A16="","",TEXT(A16,"d")) -> 26 | C16: =IF(A16="","",TEXT(A16,"mmmm")) -> março | D16: =IF(A16="","",YEAR(A16)) -> 2026 | E16: =IF(A16="","",TEXT(A16,"ddd")) -> qui | F16: =IF(A16="","",WEEKNUM(A16)) -> 13 | G16: =IF(A16="","",IF(WEEKDAY(A16,2)>5,"Final de semana","Semana")) -> Semana | H16: Uber | I16: 5 | J16: 75.65 | K16: 4 | L16: 80.85 | M16: =SUM(Tabela1[[#This Row],[Valor]]-Tabela1[[#This Row],[Combustível]]) -> 9 | N16: 71.85 | O16: 15 | P16: Etanol | Q16: 0 | R16: 0 | S16: =SUM(Tabela1[[#This Row],[Valor]]-Tabela1[[#This Row],[Alimentação]]-Tabela1[[#This Row],[Manutenção]]-Tabela1[[#This Row],[Combustível]]) -> 9 | T16: 8.8 | U16: =IFERROR(Tabela1[[#This Row],[Km]]/Tabela1[[#This Row],[Horas]],"") -> 18.9125 | V16: =IFERROR(Tabela1[[#This Row],[Valor]]/Tabela1[[#This Row],[Km]],"") -> 1.0687376 | W16: =IFERROR(Tabela1[[#This Row],[Valor]]/Tabela1[[#This Row],[Corrida]],"") -> 16.17 | X16: =IFERROR(Tabela1[[#This Row],[Km]]/Tabela1[[#This Row],[Corrida]],"") -> 15.13
A17: 46107 | B17: =IF(A17="","",TEXT(A17,"d")) -> 26 | C17: =IF(A17="","",TEXT(A17,"mmmm")) -> março | D17: =IF(A17="","",YEAR(A17)) -> 2026 | E17: =IF(A17="","",TEXT(A17,"ddd")) -> qui | F17: =IF(A17="","",WEEKNUM(A17)) -> 13 | G17: =IF(A17="","",IF(WEEKDAY(A17,2)>5,"Final de semana","Semana")) -> Semana | H17: 99 | I17: 5 | J17: 75.65 | K17: 2 | L17: 65.29 | M17: =SUM(Tabela1[[#This Row],[Valor]]-Tabela1[[#This Row],[Combustível]]) -> -6.56 | N17: 71.85 | O17: 15 | P17: Etanol | Q17: 0 | R17: 0 | S17: =SUM(Tabela1[[#This Row],[Valor]]-Tabela1[[#This Row],[Alimentação]]-Tabela1[[#This Row],[Manutenção]]-Tabela1[[#This Row],[Combustível]]) -> -6.56 | T17: 8.8 | U17: =IFERROR(Tabela1[[#This Row],[Km]]/Tabela1[[#This Row],[Horas]],"") -> 37.825 | V17: =IFERROR(Tabela1[[#This Row],[Valor]]/Tabela1[[#This Row],[Km]],"") -> 0.86305354 | W17: =IFERROR(Tabela1[[#This Row],[Valor]]/Tabela1[[#This Row],[Corrida]],"") -> 13.058 | X17: =IFERROR(Tabela1[[#This Row],[Km]]/Tabela1[[#This Row],[Corrida]],"") -> 15.13
A18: 46109 | B18: =IF(A18="","",TEXT(A18,"d")) -> 28 | C18: =IF(A18="","",TEXT(A18,"mmmm")) -> março | D18: =IF(A18="","",YEAR(A18)) -> 2026 | E18: =IF(A18="","",TEXT(A18,"ddd")) -> sáb | F18: =IF(A18="","",WEEKNUM(A18)) -> 13 | G18: =IF(A18="","",IF(WEEKDAY(A18,2)>5,"Final de semana","Semana")) -> Final de semana | H18: Uber | I18: 8 | J18: 205 | K18: 8 | L18: 390.9 | M18: =SUM(Tabela1[[#This Row],[Valor]]-Tabela1[[#This Row],[Combustível]]) -> 342 | N18: 48.9 | O18: 10 | P18: Etanol | Q18: 15 | R18: 0 | S18: =SUM(Tabela1[[#This Row],[Valor]]-Tabela1[[#This Row],[Alimentação]]-Tabela1[[#This Row],[Manutenção]]-Tabela1[[#This Row],[Combustível]]) -> 327 | T18: 10.1 | U18: =IFERROR(Tabela1[[#This Row],[Km]]/Tabela1[[#This Row],[Horas]],"") -> 25.625 | V18: =IFERROR(Tabela1[[#This Row],[Valor]]/Tabela1[[#This Row],[Km]],"") -> 1.9068293 | W18: =IFERROR(Tabela1[[#This Row],[Valor]]/Tabela1[[#This Row],[Corrida]],"") -> 48.8625 | X18: =IFERROR(Tabela1[[#This Row],[Km]]/Tabela1[[#This Row],[Corrida]],"") -> 25.625
A19: 46109 | B19: =IF(A19="","",TEXT(A19,"d")) -> 28 | C19: =IF(A19="","",TEXT(A19,"mmmm")) -> março | D19: =IF(A19="","",YEAR(A19)) -> 2026 | E19: =IF(A19="","",TEXT(A19,"ddd")) -> sáb | F19: =IF(A19="","",WEEKNUM(A19)) -> 13 | G19: =IF(A19="","",IF(WEEKDAY(A19,2)>5,"Final de semana","Semana")) -> Final de semana | H19: 99 | I19: 8 | J19: 205 | K19: 4 | L19: 201.04 | M19: =SUM(Tabela1[[#This Row],[Valor]]-Tabela1[[#This Row],[Combustível]]) -> 152.14 | N19: 48.9 | O19: 10 | P19: Etanol | Q19: 10 | R19: 0 | S19: =SUM(Tabela1[[#This Row],[Valor]]-Tabela1[[#This Row],[Alimentação]]-Tabela1[[#This Row],[Manutenção]]-Tabela1[[#This Row],[Combustível]]) -> 142.14 | T19: 10.1 | U19: =IFERROR(Tabela1[[#This Row],[Km]]/Tabela1[[#This Row],[Horas]],"") -> 51.25 | V19: =IFERROR(Tabela1[[#This Row],[Valor]]/Tabela1[[#This Row],[Km]],"") -> 0.98068293 | W19: =IFERROR(Tabela1[[#This Row],[Valor]]/Tabela1[[#This Row],[Corrida]],"") -> 25.13 | X19: =IFERROR(Tabela1[[#This Row],[Km]]/Tabela1[[#This Row],[Corrida]],"") -> 25.625
A20: 46110 | B20: =IF(A20="","",TEXT(A20,"d")) -> 29 | C20: =IF(A20="","",TEXT(A20,"mmmm")) -> março | D20: =IF(A20="","",YEAR(A20)) -> 2026 | E20: =IF(A20="","",TEXT(A20,"ddd")) -> dom | F20: =IF(A20="","",WEEKNUM(A20)) -> 14 | G20: =IF(A20="","",IF(WEEKDAY(A20,2)>5,"Final de semana","Semana")) -> Final de semana | H20: Uber | I20: 5 | J20: 106 | K20: 5 | L20: 165.13 | M20: =SUM(Tabela1[[#This Row],[Valor]]-Tabela1[[#This Row],[Combustível]]) -> 65.91 | N20: 99.22 | O20: 20 | P20: Etanol | Q20: 0 | R20: 25 | S20: =SUM(Tabela1[[#This Row],[Valor]]-Tabela1[[#This Row],[Alimentação]]-Tabela1[[#This Row],[Manutenção]]-Tabela1[[#This Row],[Combustível]]) -> 40.91 | T20: 10.1 | U20: =IFERROR(Tabela1[[#This Row],[Km]]/Tabela1[[#This Row],[Horas]],"") -> 21.2 | V20: =IFERROR(Tabela1[[#This Row],[Valor]]/Tabela1[[#This Row],[Km]],"") -> 1.5578302 | W20: =IFERROR(Tabela1[[#This Row],[Valor]]/Tabela1[[#This Row],[Corrida]],"") -> 33.026 | X20: =IFERROR(Tabela1[[#This Row],[Km]]/Tabela1[[#This Row],[Corrida]],"") -> 21.2
A21: 46110 | B21: =IF(A21="","",TEXT(A21,"d")) -> 29 | C21: =IF(A21="","",TEXT(A21,"mmmm")) -> março | D21: =IF(A21="","",YEAR(A21)) -> 2026 | E21: =IF(A21="","",TEXT(A21,"ddd")) -> dom | F21: =IF(A21="","",WEEKNUM(A21)) -> 14 | G21: =IF(A21="","",IF(WEEKDAY(A21,2)>5,"Final de semana","Semana")) -> Final de semana | H21: 99 | I21: 5 | J21: 106 | K21: 3 | L21: 114.75 | M21: =SUM(Tabela1[[#This Row],[Valor]]-Tabela1[[#This Row],[Combustível]]) -> 64.75 | N21: 50 | O21: 10 | P21: Etanol | Q21: 0 | R21: 25 | S21: =SUM(Tabela1[[#This Row],[Valor]]-Tabela1[[#This Row],[Alimentação]]-Tabela1[[#This Row],[Manutenção]]-Tabela1[[#This Row],[Combustível]]) -> 39.75 | T21: 10.1 | U21: =IFERROR(Tabela1[[#This Row],[Km]]/Tabela1[[#This Row],[Horas]],"") -> 35.333333 | V21: =IFERROR(Tabela1[[#This Row],[Valor]]/Tabela1[[#This Row],[Km]],"") -> 1.0825472 | W21: =IFERROR(Tabela1[[#This Row],[Valor]]/Tabela1[[#This Row],[Corrida]],"") -> 22.95 | X21: =IFERROR(Tabela1[[#This Row],[Km]]/Tabela1[[#This Row],[Corrida]],"") -> 21.2
A22: 46128 | B22: =IF(A22="","",TEXT(A22,"d")) -> 16 | C22: =IF(A22="","",TEXT(A22,"mmmm")) -> abril | D22: =IF(A22="","",YEAR(A22)) -> 2026 | E22: =IF(A22="","",TEXT(A22,"ddd")) -> qui | F22: =IF(A22="","",WEEKNUM(A22)) -> 16 | G22: =IF(A22="","",IF(WEEKDAY(A22,2)>5,"Final de semana","Semana")) -> Semana | H22: Uber | I22: 7 | J22: 102.1 | K22: 5 | L22: 95.38 | M22: =SUM(Tabela1[[#This Row],[Valor]]-Tabela1[[#This Row],[Combustível]]) -> 49.48 | N22: 45.9 | O22: 10 | P22: Etanol | Q22: 2 | R22: 0 | S22: =SUM(Tabela1[[#This Row],[Valor]]-Tabela1[[#This Row],[Alimentação]]-Tabela1[[#This Row],[Manutenção]]-Tabela1[[#This Row],[Combustível]]) -> 47.48 | T22: 8.7 | U22: =IFERROR(Tabela1[[#This Row],[Km]]/Tabela1[[#This Row],[Horas]],"") -> 20.42 | V22: =IFERROR(Tabela1[[#This Row],[Valor]]/Tabela1[[#This Row],[Km]],"") -> 0.93418217 | W22: =IFERROR(Tabela1[[#This Row],[Valor]]/Tabela1[[#This Row],[Corrida]],"") -> 13.625714 | X22: =IFERROR(Tabela1[[#This Row],[Km]]/Tabela1[[#This Row],[Corrida]],"") -> 14.585714
A23: 46128 | B23: =IF(A23="","",TEXT(A23,"d")) -> 16 | C23: =IF(A23="","",TEXT(A23,"mmmm")) -> abril | D23: =IF(A23="","",YEAR(A23)) -> 2026 | E23: =IF(A23="","",TEXT(A23,"ddd")) -> qui | F23: =IF(A23="","",WEEKNUM(A23)) -> 16 | G23: =IF(A23="","",IF(WEEKDAY(A23,2)>5,"Final de semana","Semana")) -> Semana | H23: 99 | I23: 5 | J23: 77.95 | K23: 3 | L23: 136.89 | M23: =SUM(Tabela1[[#This Row],[Valor]]-Tabela1[[#This Row],[Combustível]]) -> 68.04 | N23: 68.85 | O23: 15 | P23: Etanol | Q23: 2 | R23: 0 | S23: =SUM(Tabela1[[#This Row],[Valor]]-Tabela1[[#This Row],[Alimentação]]-Tabela1[[#This Row],[Manutenção]]-Tabela1[[#This Row],[Combustível]]) -> 66.04 | T23: 8.7 | U23: =IFERROR(Tabela1[[#This Row],[Km]]/Tabela1[[#This Row],[Horas]],"") -> 25.983333 | V23: =IFERROR(Tabela1[[#This Row],[Valor]]/Tabela1[[#This Row],[Km]],"") -> 1.7561257 | W23: =IFERROR(Tabela1[[#This Row],[Valor]]/Tabela1[[#This Row],[Corrida]],"") -> 27.378 | X23: =IFERROR(Tabela1[[#This Row],[Km]]/Tabela1[[#This Row],[Corrida]],"") -> 15.59
A24: 46129 | B24: =IF(A24="","",TEXT(A24,"d")) -> 17 | C24: =IF(A24="","",TEXT(A24,"mmmm")) -> abril | D24: =IF(A24="","",YEAR(A24)) -> 2026 | E24: =IF(A24="","",TEXT(A24,"ddd")) -> sex | F24: =IF(A24="","",WEEKNUM(A24)) -> 16 | G24: =IF(A24="","",IF(WEEKDAY(A24,2)>5,"Final de semana","Semana")) -> Semana | H24: Uber | I24: 8 | J24: 200 | K24: 5 | L24: 196.82 | M24: =SUM(Tabela1[[#This Row],[Valor]]-Tabela1[[#This Row],[Combustível]]) -> 129.47 | N24: 67.35 | O24: 15 | P24: Etanol | Q24: 0 | R24: 0 | S24: =SUM(Tabela1[[#This Row],[Valor]]-Tabela1[[#This Row],[Alimentação]]-Tabela1[[#This Row],[Manutenção]]-Tabela1[[#This Row],[Combustível]]) -> 129.47 | T24: 9.2 | U24: =IFERROR(Tabela1[[#This Row],[Km]]/Tabela1[[#This Row],[Horas]],"") -> 40 | V24: =IFERROR(Tabela1[[#This Row],[Valor]]/Tabela1[[#This Row],[Km]],"") -> 0.9841 | W24: =IFERROR(Tabela1[[#This Row],[Valor]]/Tabela1[[#This Row],[Corrida]],"") -> 24.6025 | X24: =IFERROR(Tabela1[[#This Row],[Km]]/Tabela1[[#This Row],[Corrida]],"") -> 25
A25: 46129 | B25: =IF(A25="","",TEXT(A25,"d")) -> 17 | C25: =IF(A25="","",TEXT(A25,"mmmm")) -> abril | D25: =IF(A25="","",YEAR(A25)) -> 2026 | E25: =IF(A25="","",TEXT(A25,"ddd")) -> sex | F25: =IF(A25="","",WEEKNUM(A25)) -> 16 | G25: =IF(A25="","",IF(WEEKDAY(A25,2)>5,"Final de semana","Semana")) -> Semana | H25: 99 | I25: 4 | J25: 100 | K25: 3 | L25: 154.79 | M25: =SUM(Tabela1[[#This Row],[Valor]]-Tabela1[[#This Row],[Combustível]]) -> 109.89 | N25: 44.9 | O25: 10 | P25: Etanol | Q25: 0 | R25: 0 | S25: =SUM(Tabela1[[#This Row],[Valor]]-Tabela1[[#This Row],[Alimentação]]-Tabela1[[#This Row],[Manutenção]]-Tabela1[[#This Row],[Combustível]]) -> 109.89 | T25: 9.2 | U25: =IFERROR(Tabela1[[#This Row],[Km]]/Tabela1[[#This Row],[Horas]],"") -> 33.333333 | V25: =IFERROR(Tabela1[[#This Row],[Valor]]/Tabela1[[#This Row],[Km]],"") -> 1.5479 | W25: =IFERROR(Tabela1[[#This Row],[Valor]]/Tabela1[[#This Row],[Corrida]],"") -> 38.6975 | X25: =IFERROR(Tabela1[[#This Row],[Km]]/Tabela1[[#This Row],[Corrida]],"") -> 25
A26: 46130 | B26: =IF(A26="","",TEXT(A26,"d")) -> 18 | C26: =IF(A26="","",TEXT(A26,"mmmm")) -> abril | D26: =IF(A26="","",YEAR(A26)) -> 2026 | E26: =IF(A26="","",TEXT(A26,"ddd")) -> sáb | F26: =IF(A26="","",WEEKNUM(A26)) -> 16 | G26: =IF(A26="","",IF(WEEKDAY(A26,2)>5,"Final de semana","Semana")) -> Final de semana | H26: Uber | I26: 5 | J26: 154.5 | K26: 3 | L26: 107.16 | M26: =SUM(Tabela1[[#This Row],[Valor]]-Tabela1[[#This Row],[Combustível]]) -> 15.36 | N26: 91.8 | O26: 20 | P26: Etanol | Q26: 0 | R26: 0 | S26: =SUM(Tabela1[[#This Row],[Valor]]-Tabela1[[#This Row],[Alimentação]]-Tabela1[[#This Row],[Manutenção]]-Tabela1[[#This Row],[Combustível]]) -> 15.36 | T26: 10.6 | U26: =IFERROR(Tabela1[[#This Row],[Km]]/Tabela1[[#This Row],[Horas]],"") -> 51.5 | V26: =IFERROR(Tabela1[[#This Row],[Valor]]/Tabela1[[#This Row],[Km]],"") -> 0.69359223 | W26: =IFERROR(Tabela1[[#This Row],[Valor]]/Tabela1[[#This Row],[Corrida]],"") -> 21.432 | X26: =IFERROR(Tabela1[[#This Row],[Km]]/Tabela1[[#This Row],[Corrida]],"") -> 30.9
A27: 46130 | B27: =IF(A27="","",TEXT(A27,"d")) -> 18 | C27: =IF(A27="","",TEXT(A27,"mmmm")) -> abril | D27: =IF(A27="","",YEAR(A27)) -> 2026 | E27: =IF(A27="","",TEXT(A27,"ddd")) -> sáb | F27: =IF(A27="","",WEEKNUM(A27)) -> 16 | G27: =IF(A27="","",IF(WEEKDAY(A27,2)>5,"Final de semana","Semana")) -> Final de semana | H27: 99 | I27: 6 | J27: 185.4 | K27: 4 | L27: 284.81 | M27: =SUM(Tabela1[[#This Row],[Valor]]-Tabela1[[#This Row],[Combustível]]) -> 170.06 | N27: 114.75 | O27: 25 | P27: Etanol | Q27: 0 | R27: 0 | S27: =SUM(Tabela1[[#This Row],[Valor]]-Tabela1[[#This Row],[Alimentação]]-Tabela1[[#This Row],[Manutenção]]-Tabela1[[#This Row],[Combustível]]) -> 170.06 | T27: 10.6 | U27: =IFERROR(Tabela1[[#This Row],[Km]]/Tabela1[[#This Row],[Horas]],"") -> 46.35 | V27: =IFERROR(Tabela1[[#This Row],[Valor]]/Tabela1[[#This Row],[Km]],"") -> 1.536192 | W27: =IFERROR(Tabela1[[#This Row],[Valor]]/Tabela1[[#This Row],[Corrida]],"") -> 47.468333 | X27: =IFERROR(Tabela1[[#This Row],[Km]]/Tabela1[[#This Row],[Corrida]],"") -> 30.9
A28: 46149 | B28: =IF(A28="","",TEXT(A28,"d")) -> 7 | C28: =IF(A28="","",TEXT(A28,"mmmm")) -> maio | D28: =IF(A28="","",YEAR(A28)) -> 2026 | E28: =IF(A28="","",TEXT(A28,"ddd")) -> qui | F28: =IF(A28="","",WEEKNUM(A28)) -> 19 | G28: =IF(A28="","",IF(WEEKDAY(A28,2)>5,"Final de semana","Semana")) -> Semana | H28: Uber | I28: 4 | J28: 100 | K28: 3 | L28: 91.05 | M28: =SUM(Tabela1[[#This Row],[Valor]]-Tabela1[[#This Row],[Combustível]]) -> 41.05 | N28: 50 | O28: 15 | P28: Etanol | Q28: 0 | R28: 0 | S28: =SUM(Tabela1[[#This Row],[Valor]]-Tabela1[[#This Row],[Alimentação]]-Tabela1[[#This Row],[Manutenção]]-Tabela1[[#This Row],[Combustível]]) -> 41.05 | T28: 9 | U28: =IFERROR(Tabela1[[#This Row],[Km]]/Tabela1[[#This Row],[Horas]],"") -> 33.333333 | V28: =IFERROR(Tabela1[[#This Row],[Valor]]/Tabela1[[#This Row],[Km]],"") -> 0.9105 | W28: =IFERROR(Tabela1[[#This Row],[Valor]]/Tabela1[[#This Row],[Corrida]],"") -> 22.7625 | X28: =IFERROR(Tabela1[[#This Row],[Km]]/Tabela1[[#This Row],[Corrida]],"") -> 25
A29: 46149 | B29: =IF(A29="","",TEXT(A29,"d")) -> 7 | C29: =IF(A29="","",TEXT(A29,"mmmm")) -> maio | D29: =IF(A29="","",YEAR(A29)) -> 2026 | E29: =IF(A29="","",TEXT(A29,"ddd")) -> qui | F29: =IF(A29="","",WEEKNUM(A29)) -> 19 | G29: =IF(A29="","",IF(WEEKDAY(A29,2)>5,"Final de semana","Semana")) -> Semana | H29: 99 | I29: 2 | J29: 40 | K29: 2 | L29: 54.8 | M29: =SUM(Tabela1[[#This Row],[Valor]]-Tabela1[[#This Row],[Combustível]]) -> 4.8 | N29: 50 | O29: 10 | P29: Etanol | Q29: 0 | R29: 0 | S29: =SUM(Tabela1[[#This Row],[Valor]]-Tabela1[[#This Row],[Alimentação]]-Tabela1[[#This Row],[Manutenção]]-Tabela1[[#This Row],[Combustível]]) -> 4.8 | T29: 9 | U29: =IFERROR(Tabela1[[#This Row],[Km]]/Tabela1[[#This Row],[Horas]],"") -> 20 | V29: =IFERROR(Tabela1[[#This Row],[Valor]]/Tabela1[[#This Row],[Km]],"") -> 1.37 | W29: =IFERROR(Tabela1[[#This Row],[Valor]]/Tabela1[[#This Row],[Corrida]],"") -> 27.4 | X29: =IFERROR(Tabela1[[#This Row],[Km]]/Tabela1[[#This Row],[Corrida]],"") -> 20
A30: 46151 | B30: =IF(A30="","",TEXT(A30,"d")) -> 9 | C30: =IF(A30="","",TEXT(A30,"mmmm")) -> maio | D30: =IF(A30="","",YEAR(A30)) -> 2026 | E30: =IF(A30="","",TEXT(A30,"ddd")) -> sáb | F30: =IF(A30="","",WEEKNUM(A30)) -> 19 | G30: =IF(A30="","",IF(WEEKDAY(A30,2)>5,"Final de semana","Semana")) -> Final de semana | H30: Uber | I30: 6 | J30: 150 | K30: 4 | L30: 145.36 | M30: =SUM(Tabela1[[#This Row],[Valor]]-Tabela1[[#This Row],[Combustível]]) -> 16.66 | N30: 128.7 | O30: 35 | P30: Etanol | Q30: 0 | R30: 450 | S30: =SUM(Tabela1[[#This Row],[Valor]]-Tabela1[[#This Row],[Alimentação]]-Tabela1[[#This Row],[Manutenção]]-Tabela1[[#This Row],[Combustível]]) -> -433.34 | T30: 9.5 | U30: =IFERROR(Tabela1[[#This Row],[Km]]/Tabela1[[#This Row],[Horas]],"") -> 37.5 | V30: =IFERROR(Tabela1[[#This Row],[Valor]]/Tabela1[[#This Row],[Km]],"") -> 0.96906667 | W30: =IFERROR(Tabela1[[#This Row],[Valor]]/Tabela1[[#This Row],[Corrida]],"") -> 24.226667 | X30: =IFERROR(Tabela1[[#This Row],[Km]]/Tabela1[[#This Row],[Corrida]],"") -> 25
A31: 46151 | B31: =IF(A31="","",TEXT(A31,"d")) -> 9 | C31: =IF(A31="","",TEXT(A31,"mmmm")) -> maio | D31: =IF(A31="","",YEAR(A31)) -> 2026 | E31: =IF(A31="","",TEXT(A31,"ddd")) -> sáb | F31: =IF(A31="","",WEEKNUM(A31)) -> 19 | G31: =IF(A31="","",IF(WEEKDAY(A31,2)>5,"Final de semana","Semana")) -> Final de semana | H31: 99 | I31: 7 | J31: 150 | K31: 4 | L31: 262.9 | M31: =SUM(Tabela1[[#This Row],[Valor]]-Tabela1[[#This Row],[Combustível]]) -> 144.7 | N31: 118.2 | O31: 30 | P31: Etanol | Q31: 0 | R31: 0 | S31: =SUM(Tabela1[[#This Row],[Valor]]-Tabela1[[#This Row],[Alimentação]]-Tabela1[[#This Row],[Manutenção]]-Tabela1[[#This Row],[Combustível]]) -> 144.7 | T31: 9.5 | U31: =IFERROR(Tabela1[[#This Row],[Km]]/Tabela1[[#This Row],[Horas]],"") -> 37.5 | V31: =IFERROR(Tabela1[[#This Row],[Valor]]/Tabela1[[#This Row],[Km]],"") -> 1.7526667 | W31: =IFERROR(Tabela1[[#This Row],[Valor]]/Tabela1[[#This Row],[Corrida]],"") -> 37.557143 | X31: =IFERROR(Tabela1[[#This Row],[Km]]/Tabela1[[#This Row],[Corrida]],"") -> 21.428571
A32: 46152 | B32: =IF(A32="","",TEXT(A32,"d")) -> 10 | C32: =IF(A32="","",TEXT(A32,"mmmm")) -> maio | D32: =IF(A32="","",YEAR(A32)) -> 2026 | E32: =IF(A32="","",TEXT(A32,"ddd")) -> dom | F32: =IF(A32="","",WEEKNUM(A32)) -> 20 | G32: =IF(A32="","",IF(WEEKDAY(A32,2)>5,"Final de semana","Semana")) -> Final de semana | H32: Uber | I32: 8 | J32: 168.9 | K32: 5 | L32: 239.5 | M32: =SUM(Tabela1[[#This Row],[Valor]]-Tabela1[[#This Row],[Combustível]]) -> 175.15 | N32: 64.35 | O32: 15 | P32: Etanol | Q32: 0 | R32: 0 | S32: =SUM(Tabela1[[#This Row],[Valor]]-Tabela1[[#This Row],[Alimentação]]-Tabela1[[#This Row],[Manutenção]]-Tabela1[[#This Row],[Combustível]]) -> 175.15 | T32: 9.7 | U32: =IFERROR(Tabela1[[#This Row],[Km]]/Tabela1[[#This Row],[Horas]],"") -> 33.78 | V32: =IFERROR(Tabela1[[#This Row],[Valor]]/Tabela1[[#This Row],[Km]],"") -> 1.4179988 | W32: =IFERROR(Tabela1[[#This Row],[Valor]]/Tabela1[[#This Row],[Corrida]],"") -> 29.9375 | X32: =IFERROR(Tabela1[[#This Row],[Km]]/Tabela1[[#This Row],[Corrida]],"") -> 21.1125
A33: 46152 | B33: =IF(A33="","",TEXT(A33,"d")) -> 10 | C33: =IF(A33="","",TEXT(A33,"mmmm")) -> maio | D33: =IF(A33="","",YEAR(A33)) -> 2026 | E33: =IF(A33="","",TEXT(A33,"ddd")) -> dom | F33: =IF(A33="","",WEEKNUM(A33)) -> 20 | G33: =IF(A33="","",IF(WEEKDAY(A33,2)>5,"Final de semana","Semana")) -> Final de semana | H33: 99 | I33: 7 | J33: 147.77 | K33: 4 | L33: 244.55 | M33: =SUM(Tabela1[[#This Row],[Valor]]-Tabela1[[#This Row],[Combustível]]) -> 201.65 | N33: 42.9 | O33: 10 | P33: Etanol | Q33: 0 | R33: 0 | S33: =SUM(Tabela1[[#This Row],[Valor]]-Tabela1[[#This Row],[Alimentação]]-Tabela1[[#This Row],[Manutenção]]-Tabela1[[#This Row],[Combustível]]) -> 201.65 | T33: 9.7 | U33: =IFERROR(Tabela1[[#This Row],[Km]]/Tabela1[[#This Row],[Horas]],"") -> 36.9425 | V33: =IFERROR(Tabela1[[#This Row],[Valor]]/Tabela1[[#This Row],[Km]],"") -> 1.6549367 | W33: =IFERROR(Tabela1[[#This Row],[Valor]]/Tabela1[[#This Row],[Corrida]],"") -> 34.935714 | X33: =IFERROR(Tabela1[[#This Row],[Km]]/Tabela1[[#This Row],[Corrida]],"") -> 21.11
A34: 46157 | B34: =IF(A34="","",TEXT(A34,"d")) -> 15 | C34: =IF(A34="","",TEXT(A34,"mmmm")) -> maio | D34: =IF(A34="","",YEAR(A34)) -> 2026 | E34: =IF(A34="","",TEXT(A34,"ddd")) -> sex | F34: =IF(A34="","",WEEKNUM(A34)) -> 20 | G34: =IF(A34="","",IF(WEEKDAY(A34,2)>5,"Final de semana","Semana")) -> Semana | H34: Uber | I34: 2 | J34: 28 | K34: 2 | L34: 67.79 | M34: =SUM(Tabela1[[#This Row],[Valor]]-Tabela1[[#This Row],[Combustível]]) -> 46.14 | N34: 21.65 | O34: 5 | P34: Etanol | Q34: 0 | R34: 0 | S34: =SUM(Tabela1[[#This Row],[Valor]]-Tabela1[[#This Row],[Alimentação]]-Tabela1[[#This Row],[Manutenção]]-Tabela1[[#This Row],[Combustível]]) -> 46.14 | T34: 8.8 | U34: =IFERROR(Tabela1[[#This Row],[Km]]/Tabela1[[#This Row],[Horas]],"") -> 14 | V34: =IFERROR(Tabela1[[#This Row],[Valor]]/Tabela1[[#This Row],[Km]],"") -> 2.4210714 | W34: =IFERROR(Tabela1[[#This Row],[Valor]]/Tabela1[[#This Row],[Corrida]],"") -> 33.895 | X34: =IFERROR(Tabela1[[#This Row],[Km]]/Tabela1[[#This Row],[Corrida]],"") -> 14
A35: 46157 | B35: =IF(A35="","",TEXT(A35,"d")) -> 15 | C35: =IF(A35="","",TEXT(A35,"mmmm")) -> maio | D35: =IF(A35="","",YEAR(A35)) -> 2026 | E35: =IF(A35="","",TEXT(A35,"ddd")) -> sex | F35: =IF(A35="","",WEEKNUM(A35)) -> 20 | G35: =IF(A35="","",IF(WEEKDAY(A35,2)>5,"Final de semana","Semana")) -> Semana | H35: 99 | I35: 9 | J35: 126 | K35: 4 | L35: 168.73 | M35: =SUM(Tabela1[[#This Row],[Valor]]-Tabela1[[#This Row],[Combustível]]) -> 53.73 | N35: 115 | O35: 32 | P35: Etanol | Q35: 15 | R35: 0 | S35: =SUM(Tabela1[[#This Row],[Valor]]-Tabela1[[#This Row],[Alimentação]]-Tabela1[[#This Row],[Manutenção]]-Tabela1[[#This Row],[Combustível]]) -> 38.73 | T35: 8.8 | U35: =IFERROR(Tabela1[[#This Row],[Km]]/Tabela1[[#This Row],[Horas]],"") -> 31.5 | V35: =IFERROR(Tabela1[[#This Row],[Valor]]/Tabela1[[#This Row],[Km]],"") -> 1.339127 | W35: =IFERROR(Tabela1[[#This Row],[Valor]]/Tabela1[[#This Row],[Corrida]],"") -> 18.747778 | X35: =IFERROR(Tabela1[[#This Row],[Km]]/Tabela1[[#This Row],[Corrida]],"") -> 14
A36: 46158 | B36: =IF(A36="","",TEXT(A36,"d")) -> 16 | C36: =IF(A36="","",TEXT(A36,"mmmm")) -> maio | D36: =IF(A36="","",YEAR(A36)) -> 2026 | E36: =IF(A36="","",TEXT(A36,"ddd")) -> sáb | F36: =IF(A36="","",WEEKNUM(A36)) -> 20 | G36: =IF(A36="","",IF(WEEKDAY(A36,2)>5,"Final de semana","Semana")) -> Final de semana | H36: Uber | I36: 5 | J36: 70.2 | K36: 3 | L36: 119.29 | M36: =SUM(Tabela1[[#This Row],[Valor]]-Tabela1[[#This Row],[Combustível]]) -> 57 | N36: 62.29 | O36: 16.7 | P36: Etanol | Q36: 25 | R36: 0 | S36: =SUM(Tabela1[[#This Row],[Valor]]-Tabela1[[#This Row],[Alimentação]]-Tabela1[[#This Row],[Manutenção]]-Tabela1[[#This Row],[Combustível]]) -> 32 | T36: 9.4 | U36: =IFERROR(Tabela1[[#This Row],[Km]]/Tabela1[[#This Row],[Horas]],"") -> 23.4 | V36: =IFERROR(Tabela1[[#This Row],[Valor]]/Tabela1[[#This Row],[Km]],"") -> 1.6992877 | W36: =IFERROR(Tabela1[[#This Row],[Valor]]/Tabela1[[#This Row],[Corrida]],"") -> 23.858 | X36: =IFERROR(Tabela1[[#This Row],[Km]]/Tabela1[[#This Row],[Corrida]],"") -> 14.04
A37: 46158 | B37: =IF(A37="","",TEXT(A37,"d")) -> 16 | C37: =IF(A37="","",TEXT(A37,"mmmm")) -> maio | D37: =IF(A37="","",YEAR(A37)) -> 2026 | E37: =IF(A37="","",TEXT(A37,"ddd")) -> sáb | F37: =IF(A37="","",WEEKNUM(A37)) -> 20 | G37: =IF(A37="","",IF(WEEKDAY(A37,2)>5,"Final de semana","Semana")) -> Final de semana | H37: 99 | I37: 16 | J37: 224.7 | K37: 6 | L37: 284.13 | M37: =SUM(Tabela1[[#This Row],[Valor]]-Tabela1[[#This Row],[Combustível]]) -> 221.84 | N37: 62.29 | O37: 16.7 | P37: Etanol | Q37: 25 | R37: 0 | S37: =SUM(Tabela1[[#This Row],[Valor]]-Tabela1[[#This Row],[Alimentação]]-Tabela1[[#This Row],[Manutenção]]-Tabela1[[#This Row],[Combustível]]) -> 196.84 | T37: 9.4 | U37: =IFERROR(Tabela1[[#This Row],[Km]]/Tabela1[[#This Row],[Horas]],"") -> 37.45 | V37: =IFERROR(Tabela1[[#This Row],[Valor]]/Tabela1[[#This Row],[Km]],"") -> 1.264486 | W37: =IFERROR(Tabela1[[#This Row],[Valor]]/Tabela1[[#This Row],[Corrida]],"") -> 17.758125 | X37: =IFERROR(Tabela1[[#This Row],[Km]]/Tabela1[[#This Row],[Corrida]],"") -> 14.04375
A38: 46159 | B38: =IF(A38="","",TEXT(A38,"d")) -> 17 | C38: =IF(A38="","",TEXT(A38,"mmmm")) -> maio | D38: =IF(A38="","",YEAR(A38)) -> 2026 | E38: =IF(A38="","",TEXT(A38,"ddd")) -> dom | F38: =IF(A38="","",WEEKNUM(A38)) -> 21 | G38: =IF(A38="","",IF(WEEKDAY(A38,2)>5,"Final de semana","Semana")) -> Final de semana | H38: Uber | I38: 1 | J38: 5.7 | K38: 2 | L38: 10.16 | M38: =SUM(Tabela1[[#This Row],[Valor]]-Tabela1[[#This Row],[Combustível]]) -> 10.16 | N38: 0 | O38: 0 | P38: Etanol | Q38: 0 | R38: 0 | S38: =SUM(Tabela1[[#This Row],[Valor]]-Tabela1[[#This Row],[Alimentação]]-Tabela1[[#This Row],[Manutenção]]-Tabela1[[#This Row],[Combustível]]) -> 10.16 | T38: 9.9 | U38: =IFERROR(Tabela1[[#This Row],[Km]]/Tabela1[[#This Row],[Horas]],"") -> 2.85 | V38: =IFERROR(Tabela1[[#This Row],[Valor]]/Tabela1[[#This Row],[Km]],"") -> 1.7824561 | W38: =IFERROR(Tabela1[[#This Row],[Valor]]/Tabela1[[#This Row],[Corrida]],"") -> 10.16 | X38: =IFERROR(Tabela1[[#This Row],[Km]]/Tabela1[[#This Row],[Corrida]],"") -> 5.7
A39: 46159 | B39: =IF(A39="","",TEXT(A39,"d")) -> 17 | C39: =IF(A39="","",TEXT(A39,"mmmm")) -> maio | D39: =IF(A39="","",YEAR(A39)) -> 2026 | E39: =IF(A39="","",TEXT(A39,"ddd")) -> dom | F39: =IF(A39="","",WEEKNUM(A39)) -> 21 | G39: =IF(A39="","",IF(WEEKDAY(A39,2)>5,"Final de semana","Semana")) -> Final de semana | H39: 99 | I39: 9 | J39: 250 | K39: 5 | L39: 304.59 | M39: =SUM(Tabela1[[#This Row],[Valor]]-Tabela1[[#This Row],[Combustível]]) -> 165.61 | N39: 138.98 | O39: 36 | P39: Etanol | Q39: 0 | R39: 0 | S39: =SUM(Tabela1[[#This Row],[Valor]]-Tabela1[[#This Row],[Alimentação]]-Tabela1[[#This Row],[Manutenção]]-Tabela1[[#This Row],[Combustível]]) -> 165.61 | T39: 9.9 | U39: =IFERROR(Tabela1[[#This Row],[Km]]/Tabela1[[#This Row],[Horas]],"") -> 50 | V39: =IFERROR(Tabela1[[#This Row],[Valor]]/Tabela1[[#This Row],[Km]],"") -> 1.21836 | W39: =IFERROR(Tabela1[[#This Row],[Valor]]/Tabela1[[#This Row],[Corrida]],"") -> 33.843333 | X39: =IFERROR(Tabela1[[#This Row],[Km]]/Tabela1[[#This Row],[Corrida]],"") -> 27.777778
A40: 46164 | B40: =IF(A40="","",TEXT(A40,"d")) -> 22 | C40: =IF(A40="","",TEXT(A40,"mmmm")) -> maio | D40: =IF(A40="","",YEAR(A40)) -> 2026 | E40: =IF(A40="","",TEXT(A40,"ddd")) -> sex | F40: =IF(A40="","",WEEKNUM(A40)) -> 21 | G40: =IF(A40="","",IF(WEEKDAY(A40,2)>5,"Final de semana","Semana")) -> Semana | H40: Uber | I40: 5 | J40: 144.8 | K40: 4 | L40: 145.24 | M40: =SUM(Tabela1[[#This Row],[Valor]]-Tabela1[[#This Row],[Combustível]]) -> 45.71 | N40: 99.53 | O40: 25.4 | P40: Etanol | Q40: 0 | R40: 0 | S40: =SUM(Tabela1[[#This Row],[Valor]]-Tabela1[[#This Row],[Alimentação]]-Tabela1[[#This Row],[Manutenção]]-Tabela1[[#This Row],[Combustível]]) -> 45.71 | T40: 10.3 | U40: =IFERROR(Tabela1[[#This Row],[Km]]/Tabela1[[#This Row],[Horas]],"") -> 36.2 | V40: =IFERROR(Tabela1[[#This Row],[Valor]]/Tabela1[[#This Row],[Km]],"") -> 1.0030387 | W40: =IFERROR(Tabela1[[#This Row],[Valor]]/Tabela1[[#This Row],[Corrida]],"") -> 29.048 | X40: =IFERROR(Tabela1[[#This Row],[Km]]/Tabela1[[#This Row],[Corrida]],"") -> 28.96
...

Sheet Metricas
B2: Tempo | K2: Operação | M2: Receita | N2: Custos | P2: Resultado | R2: Indicadores
B4: Semana | C4: Dia | D4: Mês | E4: Ano | F4: Semana2 | G4: Semana do ano | H4: Tipo de dia | I4: Dias trabalhado | J4: Horas trabalhadas | K4: Total corridas | L4: KM total | M4: Receita total | N4: Combustivel total | O4: Despesas total | P4: Receita | Q4: Lucro liquido | R4: Ganho po KM | S4: Ganho por hora | T4: Lucro por hora | U4: Corrida por hora | V4: Receita media por corrida | W4: KM medio corrida | X4: Lucro medio dia | Y4: Corrida por KM
B5: =Registro!A2 -> 46088 | C5: =IF(B5="","",DAY(B5)) -> 7 | D5: =IF(B5="","",TEXT(B5,"mmmm")) -> março | E5: =IF(B5="","",YEAR(B5)) -> 2026 | F5: =IF(B5="","",TEXT(B5,"dddd")) -> sábado | G5: =IF(B5="","",WEEKNUM(B5)) -> 10 | H5: =IF(B5="","",IF(WEEKDAY(B5,2)>5,"Final de semana","Semana")) -> Final de semana | I5: =COUNTA(_xlfn.UNIQUE(Registro!A2:A538)) -> 36 | J5: =SUM(Registro!K:K) -> 277 | K5: =SUM(Registro!I:I) -> 422 | L5: =SUM(Registro!J:J) -> 8867.91 | M5: =SUM(Registro!L:L) -> 11430.83 | N5: =SUM(Registro!N:N) -> 4685.34 | O5: =SUM(Registro!Q2+Registro!R2) -> 0 | P5: =SUM(M5-N5) -> 6745.49 | Q5: =SUM(P5-O5) -> 6745.49 | R5: =SUM(M5/L5) -> 1.2890106 | S5: =SUM(M5/J5) -> 41.266534 | T5: =SUM(Q5/J5) -> 24.351949 | U5: =SUM(K5/J5) -> 1.5234657 | V5: =SUM(M5/K5) -> 27.087275 | W5: =SUM(L5/K5) -> 21.014005 | X5: =SUM(M5/I5) -> 317.52306 | Y5: =SUM(L5/K5) -> 21.014005
B6: =Registro!A3 -> 46088 | C6: =IF(B6="","",DAY(B6)) -> 7 | D6: =IF(B6="","",TEXT(B6,"mmmm")) -> março | E6: =IF(B6="","",YEAR(B6)) -> 2026 | F6: =IF(B6="","",TEXT(B6,"dddd")) -> sábado | G6: =IF(B6="","",WEEKNUM(B6)) -> 10 | H6: =IF(B6="","",IF(WEEKDAY(B6,2)>5,"Final de semana","Semana")) -> Final de semana
B7: =Registro!A4 -> 46093 | C7: =IF(B7="","",DAY(B7)) -> 12 | D7: =IF(B7="","",TEXT(B7,"mmmm")) -> março | E7: =IF(B7="","",YEAR(B7)) -> 2026 | F7: =IF(B7="","",TEXT(B7,"dddd")) -> quinta-feira | G7: =IF(B7="","",WEEKNUM(B7)) -> 11 | H7: =IF(B7="","",IF(WEEKDAY(B7,2)>5,"Final de semana","Semana")) -> Semana
B8: =Registro!A5 -> 46093 | C8: =IF(B8="","",DAY(B8)) -> 12 | D8: =IF(B8="","",TEXT(B8,"mmmm")) -> março | E8: =IF(B8="","",YEAR(B8)) -> 2026 | F8: =IF(B8="","",TEXT(B8,"dddd")) -> quinta-feira | G8: =IF(B8="","",WEEKNUM(B8)) -> 11 | H8: =IF(B8="","",IF(WEEKDAY(B8,2)>5,"Final de semana","Semana")) -> Semana
B9: =Registro!A6 -> 46094 | C9: =IF(B9="","",DAY(B9)) -> 13 | D9: =IF(B9="","",TEXT(B9,"mmmm")) -> março | E9: =IF(B9="","",YEAR(B9)) -> 2026 | F9: =IF(B9="","",TEXT(B9,"dddd")) -> sexta-feira | G9: =IF(B9="","",WEEKNUM(B9)) -> 11 | H9: =IF(B9="","",IF(WEEKDAY(B9,2)>5,"Final de semana","Semana")) -> Semana
B10: =Registro!A7 -> 46094 | C10: =IF(B10="","",DAY(B10)) -> 13 | D10: =IF(B10="","",TEXT(B10,"mmmm")) -> março | E10: =IF(B10="","",YEAR(B10)) -> 2026 | F10: =IF(B10="","",TEXT(B10,"dddd")) -> sexta-feira | G10: =IF(B10="","",WEEKNUM(B10)) -> 11 | H10: =IF(B10="","",IF(WEEKDAY(B10,2)>5,"Final de semana","Semana")) -> Semana
B11: =Registro!A8 -> 46096 | C11: =IF(B11="","",DAY(B11)) -> 15 | D11: =IF(B11="","",TEXT(B11,"mmmm")) -> março | E11: =IF(B11="","",YEAR(B11)) -> 2026 | F11: =IF(B11="","",TEXT(B11,"dddd")) -> domingo | G11: =IF(B11="","",WEEKNUM(B11)) -> 12 | H11: =IF(B11="","",IF(WEEKDAY(B11,2)>5,"Final de semana","Semana")) -> Final de semana
B12: =Registro!A9 -> 46096 | C12: =IF(B12="","",DAY(B12)) -> 15 | D12: =IF(B12="","",TEXT(B12,"mmmm")) -> março | E12: =IF(B12="","",YEAR(B12)) -> 2026 | F12: =IF(B12="","",TEXT(B12,"dddd")) -> domingo | G12: =IF(B12="","",WEEKNUM(B12)) -> 12 | H12: =IF(B12="","",IF(WEEKDAY(B12,2)>5,"Final de semana","Semana")) -> Final de semana
B13: =Registro!A10 -> 46100 | C13: =IF(B13="","",DAY(B13)) -> 19 | D13: =IF(B13="","",TEXT(B13,"mmmm")) -> março | E13: =IF(B13="","",YEAR(B13)) -> 2026 | F13: =IF(B13="","",TEXT(B13,"dddd")) -> quinta-feira | G13: =IF(B13="","",WEEKNUM(B13)) -> 12 | H13: =IF(B13="","",IF(WEEKDAY(B13,2)>5,"Final de semana","Semana")) -> Semana
B14: =Registro!A11 -> 46100 | C14: =IF(B14="","",DAY(B14)) -> 19 | D14: =IF(B14="","",TEXT(B14,"mmmm")) -> março | E14: =IF(B14="","",YEAR(B14)) -> 2026 | F14: =IF(B14="","",TEXT(B14,"dddd")) -> quinta-feira | G14: =IF(B14="","",WEEKNUM(B14)) -> 12 | H14: =IF(B14="","",IF(WEEKDAY(B14,2)>5,"Final de semana","Semana")) -> Semana
B15: =Registro!A12 -> 46101 | C15: =IF(B15="","",DAY(B15)) -> 20 | D15: =IF(B15="","",TEXT(B15,"mmmm")) -> março | E15: =IF(B15="","",YEAR(B15)) -> 2026 | F15: =IF(B15="","",TEXT(B15,"dddd")) -> sexta-feira | G15: =IF(B15="","",WEEKNUM(B15)) -> 12 | H15: =IF(B15="","",IF(WEEKDAY(B15,2)>5,"Final de semana","Semana")) -> Semana
B16: =Registro!A13 -> 46101 | C16: =IF(B16="","",DAY(B16)) -> 20 | D16: =IF(B16="","",TEXT(B16,"mmmm")) -> março | E16: =IF(B16="","",YEAR(B16)) -> 2026 | F16: =IF(B16="","",TEXT(B16,"dddd")) -> sexta-feira | G16: =IF(B16="","",WEEKNUM(B16)) -> 12 | H16: =IF(B16="","",IF(WEEKDAY(B16,2)>5,"Final de semana","Semana")) -> Semana
B17: =Registro!A14 -> 46103 | C17: =IF(B17="","",DAY(B17)) -> 22 | D17: =IF(B17="","",TEXT(B17,"mmmm")) -> março | E17: =IF(B17="","",YEAR(B17)) -> 2026 | F17: =IF(B17="","",TEXT(B17,"dddd")) -> domingo | G17: =IF(B17="","",WEEKNUM(B17)) -> 13 | H17: =IF(B17="","",IF(WEEKDAY(B17,2)>5,"Final de semana","Semana")) -> Final de semana
... B30: =Registro!A27 -> 46130 | C30: =IF(B30="","",DAY(B30)) -> 18 | D30: =IF(B30="","",TEXT(B30,"mmmm")) -> abril | E30: =IF(B30="","",YEAR(B30)) -> 2026 | F30: =IF(B30="","",TEXT(B30,"dddd")) -> sábado | G30: =IF(B30="","",WEEKNUM(B30)) -> 16 | H30: =IF(B30="","",IF(WEEKDAY(B30,2)>5,"Final de semana","Semana")) -> Final de semana
E43: =IF(B43="","",YEAR(B43)) | F43: =IF(B43="","",TEXT(B43,"dddd")) | G43: =IF(B43="","",WEEKNUM(B43)) | H43: =IF(B43="","",IF(WEEKDAY(B43,2)>5,"Final de semana","Semana"))
E44: =IF(B44="","",YEAR(B44)) | F44: =IF(B44="","",TEXT(B44,"dddd")) | G44: =IF(B44="","",WEEKNUM(B44)) | H44: =IF(B44="","",IF(WEEKDAY(B44,2)>5,"Final de semana","Semana"))
E45: =IF(B45="","",YEAR(B45)) | H45: =IF(B45="","",IF(WEEKDAY(B45,2)>5,"Final de semana","Semana"))
H46: =IF(B46="","",IF(WEEKDAY(B46,2)>5,"Final de semana","Semana"))
